### 2.5 Esempi pratici di gestione delle eccezioni

La gestione delle eccezioni è un aspetto fondamentale della programmazione in Java. Gli esempi pratici aiutano a comprendere come usare correttamente i blocchi try, catch e finally. In questa sezione, verranno illustrati alcuni casi d'uso comuni.

#### 2.5.1 Gestione di eccezione singola 

Ecco un esempio semplice in cui si cerca di dividere due numeri. Un'eccezione viene sollevata se il divisore è zero (ArithmeticException).

```java
public class Divisione {
    public static void main(String[] args) {
        int numeratore = 10;
        int denominatore = 0;
        try {
            int risultato = numeratore / denominatore;
            System.out.println("Risultato: " + risultato);
        } catch (ArithmeticException e) {
            System.out.println("Errore: Divisione per zero!");
        }
    }
}
```

In questo esempio, la divisione genera un'eccezione perché il denominatore è zero. Il blocco `catch` cattura l'eccezione e visualizza un messaggio di errore. Senza il blocco `try-catch`, il programma terminerebbe in modo anomalo.

#### 2.5.2 Gestione di eccezioni multiple con blocchi catch multipli

Quando un blocco `try` può sollevare più tipi di eccezioni, possiamo gestirli con blocchi `catch` multipli. Ecco un esempio in cui gestiamo sia un'eccezione di divisione per zero che una `NullPointerException`.

```java
public class MultiCatch {
    public static void main(String[] args) {
        String[] array = null;
        try {
            int numero = 10 / 0; // Genera ArithmeticException
            System.out.println(array[0]); // Genera NullPointerException
        } catch (ArithmeticException e) {
            System.out.println("Errore: Divisione per zero!");
        } catch (NullPointerException e) {
            System.out.println("Errore: Accesso a un array nullo!");
        }
    }
}
```

In questo caso, il blocco `try` contiene due istruzioni che potrebbero sollevare eccezioni diverse. Il programma gestisce ogni eccezione separatamente nei rispettivi blocchi `catch`.

#### 2.5.3 Utilizzo del blocco finally

Il blocco `finally` è utile per eseguire operazioni di pulizia indipendentemente dal fatto che un'eccezione sia stata sollevata o meno. Ecco un esempio che utilizza `finally` per chiudere una risorsa (come un file o una connessione).

```java
import java.io.*;

public class FileLettura {
    public static void main(String[] args) {
        BufferedReader reader = null;
        try {
            reader = new BufferedReader(new FileReader("file.txt"));
            System.out.println(reader.readLine());
        } catch (IOException e) {
            System.out.println("Errore nella lettura del file: " + e.getMessage());
        } finally {
            try {
                if (reader != null) {
                    reader.close();
                }
            } catch (IOException e) {
                System.out.println("Errore nella chiusura del file: " + e.getMessage());
            }
        }
    }
}
```

In questo esempio, il blocco `finally` viene sempre eseguito e tenta di chiudere il file, indipendentemente dal successo o dal fallimento della lettura. Anche se viene sollevata un'eccezione durante la lettura, il blocco `finally` garantisce che la risorsa venga chiusa correttamente.

#### 2.5.4 Sollevare eccezioni personalizzate

In alcuni casi, potrebbe essere necessario creare e sollevare eccezioni personalizzate. Ecco un esempio di come creare un'eccezione personalizzata.

```java
class NumeroNegativoException extends Exception {
    public NumeroNegativoException(String messaggio) {
        super(messaggio);
    }
}

public class TestEccezionePersonalizzata {
    public static void main(String[] args) {
        try {
            controllaNumero(-5);
        } catch (NumeroNegativoException e) {
            System.out.println(e.getMessage());
        }
    }

    public static void controllaNumero(int numero) throws NumeroNegativoException {
        if (numero < 0) {
            throw new NumeroNegativoException("Errore: Numero negativo!" );
        }
        System.out.println("Numero: " + numero);
    }
}
```

In questo esempio, è stata creata un'eccezione personalizzata chiamata `NumeroNegativoException`. Il metodo `controllaNumero` lancia questa eccezione se il numero passato è negativo. Il blocco `try-catch` nella funzione `main` gestisce l'eccezione.

### Conclusione

Questi esempi pratici dimostrano come gestire eccezioni diverse utilizzando i costrutti `try`, `catch` e `finally`. La gestione delle eccezioni consente di rendere i programmi più robusti e resilienti agli errori imprevisti, migliorando l'affidabilità generale del codice.

---
[INDICE](README.md)

